<?xml version="1.0" encoding="utf-8"?>
<!-- This URDF was automatically created by SolidWorks to URDF Exporter! Originally created by Stephen Brawner (brawner@gmail.com) 
     Commit Version: 1.6.0-1-g15f4949  Build Version: 1.6.7594.29634
     For more information, please see http://wiki.ros.org/sw_urdf_exporter -->
<robot xmlns:xacro="http://www.ros.org/wiki/xacro" name="my_robot">
  <link
    name="base_link">
    <inertial>
      <origin
        xyz="-0.000118655761012276 2.48337202080062E-07 0.0488032071531479"
        rpy="0 0 0" />
      <mass
        value="0.467996005301711" />
      <inertia
        ixx="0.000361795815083131"
        ixy="5.61764733440739E-11"
        ixz="-1.36877587169084E-07"
        iyy="0.000359832165777065"
        iyz="1.99446545141866E-10"
        izz="0.000507420601912116" />
    </inertial>
    <visual>
      <origin
        xyz="0 0 0"
        rpy="0 0 0" />
      <geometry>
        <mesh
          filename="package://my_arm_robot/meshes/base_link.STL" />
      </geometry>
      <material
        name="">
        <color
          rgba="0.752941176470588 0.752941176470588 0.752941176470588 1" />
      </material>
    </visual>
    <collision>
      <origin
        xyz="0 0 0"
        rpy="0 0 0" />
      <geometry>
        <mesh
          filename="package://my_arm_robot/meshes/base_link.STL" />
      </geometry>
    </collision>
  </link>
  <link
    name="Link_1">
    <inertial>
      <origin
        xyz="5.7583E-05 -0.00066166 0.040226"
        rpy="0 0 0" />
      <mass
        value="0.35373" />
      <inertia
        ixx="0.00021017"
        ixy="-3.8243E-06"
        ixz="2.1832E-06"
        iyy="0.00025369"
        iyz="-2.5034E-05"
        izz="0.00018361" />
    </inertial>
    <visual>
      <origin
        xyz="0 0 0"
        rpy="0 0 0" />
      <geometry>
        <mesh
          filename="package://my_arm_robot/meshes/Link_1.STL" />
      </geometry>
      <material
        name="">
        <color
          rgba="0.75294 0.75294 0.75294 1" />
      </material>
    </visual>
    <collision>
      <origin
        xyz="0 0 0"
        rpy="0 0 0" />
      <geometry>
        <mesh
          filename="package://my_arm_robot/meshes/Link_1.STL" />
      </geometry>
    </collision>
  </link>
  <joint
    name="Link_1_joint"
    type="revolute">
    <origin
      xyz="0 0 0.122"
      rpy="0 0 0" />
    <parent
      link="base_link" />
    <child
      link="Link_1" />
    <axis
      xyz="0 0 -1" />
    <limit
      lower="-1.57"
      upper="1.57"
      effort="100"
      velocity="2" />
  </joint>
  <link
    name="Link_2">
    <inertial>
      <origin
        xyz="0.055 -1.3239E-14 0.014552"
        rpy="0 0 0" />
      <mass
        value="0.32748" />
      <inertia
        ixx="0.00014536"
        ixy="1.8291E-19"
        ixz="-6.7763E-21"
        iyy="0.0007689"
        iyz="3.7269E-20"
        izz="0.0008667" />
    </inertial>
    <visual>
      <origin
        xyz="0 0 0"
        rpy="0 0 0" />
      <geometry>
        <mesh
          filename="package://my_arm_robot/meshes/Link_2.STL" />
      </geometry>
      <material
        name="">
        <color
          rgba="0.79216 0.81961 0.92941 1" />
      </material>
    </visual>
    <collision>
      <origin
        xyz="0 0 0"
        rpy="0 0 0" />
      <geometry>
        <mesh
          filename="package://my_arm_robot/meshes/Link_2.STL" />
      </geometry>
    </collision>
  </link>
  <joint
    name="Link_2_joint"
    type="revolute">
    <origin
      xyz="0.0047777 -0.054792 0.046"
      rpy="1.5708 -0.75408 0.086978" />
    <parent
      link="Link_1" />
    <child
      link="Link_2" />
    <axis
      xyz="0 0 -1" />
    <limit
      lower="-1.57"
      upper="1.57"
      effort="100"
      velocity="2" />
  </joint>
  <link
    name="Link_3">
    <inertial>
      <origin
        xyz="0.0083382 -0.037856 0.05699"
        rpy="0 0 0" />
      <mass
        value="0.64467" />
      <inertia
        ixx="0.00069418"
        ixy="2.7032E-05"
        ixz="-3.5781E-07"
        iyy="0.00035252"
        iyz="-8.8078E-05"
        izz="0.00068737" />
    </inertial>
    <visual>
      <origin
        xyz="0 0 0"
        rpy="0 0 0" />
      <geometry>
        <mesh
          filename="package://my_arm_robot/meshes/Link_3.STL" />
      </geometry>
      <material
        name="">
        <color
          rgba="0.79216 0.81961 0.92941 1" />
      </material>
    </visual>
    <collision>
      <origin
        xyz="0 0 0"
        rpy="0 0 0" />
      <geometry>
        <mesh
          filename="package://my_arm_robot/meshes/Link_3.STL" />
      </geometry>
    </collision>
  </link>
  <joint
    name="Link_3_joint"
    type="revolute">
    <origin
      xyz="0.11 0 0"
      rpy="3.1416 0 -0.75408" />
    <parent
      link="Link_2" />
    <child
      link="Link_3" />
    <axis
      xyz="0 0 1" />
    <limit
      lower="-1.57"
      upper="1.57"
      effort="100"
      velocity="2" />
  </joint>
  <link
    name="Link_4">
    <inertial>
      <origin
        xyz="8.1742E-05 -0.0037326 0.044951"
        rpy="0 0 0" />
      <mass
        value="0.35757" />
      <inertia
        ixx="0.00025319"
        ixy="-6.6279E-07"
        ixz="-9.0438E-07"
        iyy="0.00028342"
        iyz="4.1327E-05"
        izz="0.00020218" />
    </inertial>
    <visual>
      <origin
        xyz="0 0 0"
        rpy="0 0 0" />
      <geometry>
        <mesh
          filename="package://my_arm_robot/meshes/Link_4.STL" />
      </geometry>
      <material
        name="">
        <color
          rgba="0.75294 0.75294 0.75294 1" />
      </material>
    </visual>
    <collision>
      <origin
        xyz="0 0 0"
        rpy="0 0 0" />
      <geometry>
        <mesh
          filename="package://my_arm_robot/meshes/Link_4.STL" />
      </geometry>
    </collision>
  </link>
  <joint
    name="Link_4_joint"
    type="revolute">
    <origin
      xyz="0.057193 -0.043058 0.055"
      rpy="-1.5708 0.13232 -0.85642" />
    <parent
      link="Link_3" />
    <child
      link="Link_4" />
    <axis
      xyz="0 0 -1" />
    <limit
      lower="-1.57"
      upper="1.57"
      effort="50"
      velocity="2" />
  </joint>
  <link
    name="Link_5">
    <inertial>
      <origin
        xyz="0.046287 2.9031E-07 -0.024452"
        rpy="0 0 0" />
      <mass
        value="0.18274" />
      <inertia
        ixx="0.00020467"
        ixy="-4.253E-11"
        ixz="7.6165E-05"
        iyy="0.0002796"
        iyz="2.4385E-10"
        izz="0.00023272" />
    </inertial>
    <visual>
      <origin
        xyz="0 0 0"
        rpy="0 0 0" />
      <geometry>
        <mesh
          filename="package://my_arm_robot/meshes/Link_5.STL" />
      </geometry>
      <material
        name="">
        <color
          rgba="0.79216 0.81961 0.92941 1" />
      </material>
    </visual>
    <collision>
      <origin
        xyz="0 0 0"
        rpy="0 0 0" />
      <geometry>
        <mesh
          filename="package://my_arm_robot/meshes/Link_5.STL" />
      </geometry>
    </collision>
  </link>
  <joint
    name="Link_5_joint"
    type="revolute">
    <origin
      xyz="-0.00094211 0.04299 0.056"
      rpy="1.5708 -1.2184 -3.1197" />
    <parent
      link="Link_4" />
    <child
      link="Link_5" />
    <axis
      xyz="0 0 -1" />
    <limit
      lower="-1.57"
      upper="1.57"
      effort="50"
      velocity="2" />
  </joint>
  <link
    name="Link_6">
    <inertial>
      <origin
        xyz="9.3082E-05 -0.00011886 -0.011318"
        rpy="0 0 0" />
      <mass
        value="0.033013" />
      <inertia
        ixx="4.9309E-06"
        ixy="-5.7312E-08"
        ixz="1.7745E-08"
        iyy="4.9634E-06"
        iyz="-2.4198E-08"
        izz="9.2017E-06" />
    </inertial>
    <visual>
      <origin
        xyz="0 0 0"
        rpy="0 0 0" />
      <geometry>
        <mesh
          filename="package://my_arm_robot/meshes/Link_6.STL" />
      </geometry>
      <material
        name="">
        <color
          rgba="0.75294 0.75294 0.75294 1" />
      </material>
    </visual>
    <collision>
      <origin
        xyz="0 0 0"
        rpy="0 0 0" />
      <geometry>
        <mesh
          filename="package://my_arm_robot/meshes/Link_6.STL" />
      </geometry>
    </collision>
  </link>
  <joint
    name="Link_6_joint"
    type="revolute">
    <origin
      xyz="0.084 0 -0.043"
      rpy="1.5708 0.016437 1.5708" />
    <parent
      link="Link_5" />
    <child
      link="Link_6" />
    <axis
      xyz="0 0 -1" />
    <limit
      lower="-1.57"
      upper="1.57"
      effort="50"
      velocity="2" />
  </joint>
  <link
    name="Base_Gap">
    <inertial>
      <origin
        xyz="0.0052546 0.00046579 0.023619"
        rpy="0 0 0" />
      <mass
        value="0.02487" />
      <inertia
        ixx="6.1843E-06"
        ixy="8.3674E-09"
        ixz="-9.252E-08"
        iyy="4.0012E-06"
        iyz="-3.9373E-08"
        izz="2.4924E-06" />
    </inertial>
    <visual>
      <origin
        xyz="0 0 0"
        rpy="0 0 0" />
      <geometry>
        <mesh
          filename="package://my_arm_robot/meshes/Base_Gap.STL" />
      </geometry>
      <material
        name="">
        <color
          rgba="0.75294 0.75294 0.75294 1" />
      </material>
    </visual>
    <collision>
      <origin
        xyz="0 0 0"
        rpy="0 0 0" />
      <geometry>
        <mesh
          filename="package://my_arm_robot/meshes/Base_Gap.STL" />
      </geometry>
    </collision>
  </link>
  <joint
    name="Base_Gap_joint"
    type="fixed">
    <origin
      xyz="0 0 0.008"
      rpy="0 0 1.6175" />
    <parent
      link="Link_6" />
    <child
      link="Base_Gap" />
    <axis
      xyz="0 0 0" />
  </joint>
  <link
    name="finger_right">
    <inertial>
      <origin
        xyz="0.022391 -0.0035934 -0.007"
        rpy="0 0 0" />
      <mass
        value="0.0029678" />
      <inertia
        ixx="7.8507E-08"
        ixy="1.9967E-07"
        ixz="4.3013E-23"
        iyy="8.4605E-07"
        iyz="-3.3087E-23"
        izz="9.1493E-07" />
    </inertial>
    <visual>
      <origin
        xyz="0 0 0"
        rpy="0 0 0" />
      <geometry>
        <mesh
          filename="package://my_arm_robot/meshes/finger_right.STL" />
      </geometry>
      <material
        name="">
        <color
          rgba="0.79216 0.81961 0.92941 1" />
      </material>
    </visual>
    <collision>
      <origin
        xyz="0 0 0"
        rpy="0 0 0" />
      <geometry>
        <mesh
          filename="package://my_arm_robot/meshes/finger_right.STL" />
      </geometry>
    </collision>
  </link>
  <joint
    name="gripper_right_joint"
    type="revolute">
    <origin
      xyz="0.0155 0.033007 0.054693"
      rpy="-1.5708 -1.1863 -1.5708" />
    <parent
      link="Base_Gap" />
    <child
      link="finger_right" />
    <axis
      xyz="0 0 -1" />
    <limit
      lower="-1.57"
      upper="1.57"
      effort="50"
      velocity="1" />
  </joint>
  <link
    name="finger_left">
    <inertial>
      <origin
        xyz="0.022391 0.0035934 -0.007"
        rpy="0 0 0" />
      <mass
        value="0.0029678" />
      <inertia
        ixx="7.8507E-08"
        ixy="-1.9967E-07"
        ixz="5.7903E-23"
        iyy="8.4605E-07"
        iyz="4.3013E-23"
        izz="9.1493E-07" />
    </inertial>
    <visual>
      <origin
        xyz="0 0 0"
        rpy="0 0 0" />
      <geometry>
        <mesh
          filename="package://my_arm_robot/meshes/finger_left.STL" />
      </geometry>
      <material
        name="">
        <color
          rgba="0.79216 0.81961 0.92941 1" />
      </material>
    </visual>
    <collision>
      <origin
        xyz="0 0 0"
        rpy="0 0 0" />
      <geometry>
        <mesh
          filename="package://my_arm_robot/meshes/finger_left.STL" />
      </geometry>
    </collision>
  </link>
  <joint
    name="gripper_left_joint"
    type="revolute">
    <origin
      xyz="0.0155 -0.032928 0.054756"
      rpy="1.5708 -1.1863 1.5708" />
    <parent
      link="Base_Gap" />
    <child
      link="finger_left" />
    <axis
      xyz="0 0 -1" />
    <limit
      lower="-1.57"
      upper="1.57"
      effort="50"
      velocity="1" />
    <mimic
      joint="gripper_right_joint"
      multiplier="-1"
      offset="0" />
  </joint>
  <link name="tool_center_point" />

  <joint name="tcp_joint" type="fixed">
    <parent link="Link_6"/>
    <child link="tool_center_point"/>
    <!-- QUAN TRỌNG: Cần chỉnh xyz và rpy ở đây -->
    <!-- Giả sử kẹp dài khoảng 15cm (0.15m) dọc theo trục Z của Link_6 -->
    <!-- Bạn cần đo thực tế từ mặt bích Link_6 đến điểm giữa 2 đầu ngón tay -->
    <origin xyz="0 0 0.1" rpy="0 0 0"/> 
  </joint>
</robot>